Workbook

Sheet README
A1: Carcinome Billing Tracker
A2: How this workbook works
A4: Sheet | B4: Purpose
A5: Patient Bills | B5: Same layout as before - ID Number, Patient Name, Patient Number, Notes, then one block per infusion round. Each round has: Fixed Charges (flat fee, manual), Consumable (auto-pulled MRP), Nursing (auto-pulled billed amount), Carcinome (auto-calculated profit for that round), Total Charges (Fixed+Consumable+Nursing), Total Received, Balance, and Payment Status. Round 1 is billed and closed before Round 2, etc.
A6: Nursing Charges | B6: Log nursing per Patient ID + Round. Supports a Fixed Package rate or an Hourly rate (shifts x rate) for the "Amount Billed to Patient" column. Separately enter "Amount Paid to Nurse" - the actual amount the nurse is paid, which is usually less than what the patient is billed. The difference is your nursing margin. Feeds Patient Bills and Nurse Payments.
A7: Nursing Rate Card | B7: Your standard nursing rates for reference (24-hr package, 12-hr package, per-visit, per-hour). Edit the numbers to your real rates - these are placeholder assumptions.
A8: Consumables Master | B8: Your price list: MRP (billed to patient) vs Landing Price (your cost) per item, with margin calculated.
A9: Consumable Usage | B9: Log consumables per Patient ID + Round - just ONE row per round. Enter the total MRP you're charging the patient and the total Landing (supplier) cost for that round; no need to itemize each medicine. Margin calculates automatically. Feeds Patient Bills.
A10: Nurse Payments | B10: What each nurse is owed for a billing period, what's been paid, and what's pending.
A11: Overall Summary | B11: Dashboard totals across everything.
A13: Color legend
A14: Blue text on pale yellow | B14: Cells you type into.
A15: Green text | B15: Pulled automatically from another sheet - don't overwrite.
A16: Black text | B16: Calculated by formula - don't overwrite.
A18: Key linking fields | B18: 'ID Number' (Patient ID, e.g. CC2026001) connects every sheet. 'Round' number (1, 2, 3...) connects a charge to the right round on Patient Bills. Keep the ID Number spelling and Round number consistent across sheets or the totals will show 0.
A19: Fixed Charges | B19: There's a dedicated "Fixed Charges" column inside each round block on Patient Bills - use it for any flat/package fee for that round (procedure fee, etc.) on top of nursing + consumables. This amount is treated as pure profit (Carcinome). Leave blank if not applicable.
A20: Carcinome (₹) column | B20: Your actual profit for that round: Fixed Charges (100% profit) + (Nursing billed - Nursing paid to nurse) + (Consumable MRP - Consumable landing cost). Automatically calculated - don't overwrite. Rolls up into "Total Carcinome Profit" on Overall Summary.
A21: Need more than 16 rounds for a patient? | B21: Copy the last round block's 10 columns and paste them after Round 16, following the same header pattern.

Sheet Patient Bills
A1: Patient Bills - Round by Round
A2: Round 1 is billed & closed before Round 2 opens, etc. Total Charges = Nursing + Consumables (auto) + Fixed Charges (you enter).
A4: ID Number | B4: Patient Name | C4: Patient Number | E4: Notes | F4: Round 1 | P4: Round 2 | Z4: Round 3 | AJ4: Round 4 | AT4: Round 5 | BD4: Round 6 | BN4: Round 7 | BX4: Round 8 | CH4: Round 9 | CR4: Round 10 | DB4: Round 11 | DL4: Round 12 | DV4: Round 13 | EF4: Round 14 | EP4: Round 15 | EZ4: Round 16 | FJ4: Round 17
F5: Service | G5: Infusion Date | H5: Fixed Charges (₹) | I5: Consumable (₹) | J5: Nursing (₹) | K5: Carcinome (₹) | L5: Total Charges (₹) | N5: Balance (₹) | O5: Payment Status | P5: Service | Q5: Infusion Date | R5: Fixed Charges (₹) | S5: Consumable (₹) | T5: Nursing (₹) | U5: Carcinome (₹) | V5: Total Charges (₹) | W5: Total Received (₹) | X5: Balance (₹) | Y5: Payment Status | Z5: Service | AA5: Infusion Date | AB5: Fixed Charges (₹) | AC5: Consumable (₹) | AD5: Nursing (₹) | AE5: Carcinome (₹) | AF5: Total Charges (₹) | AG5: Total Received (₹) | AH5: Balance (₹) | AI5: Payment Status | AJ5: Service | AK5: Infusion Date | AL5: Fixed Charges (₹) | AM5: Consumable (₹) | AN5: Nursing (₹) | AO5: Carcinome (₹) | AP5: Total Charges (₹) | AQ5: Total Received (₹) | AR5: Balance (₹) | AS5: Payment Status | AT5: Service | AU5: Infusion Date | AV5: Fixed Charges (₹) | AW5: Consumable (₹) | AX5: Nursing (₹) | AY5: Carcinome (₹) | AZ5: Total Charges (₹) | BA5: Total Received (₹) | BB5: Balance (₹) | BC5: Payment Status | BD5: Service | BE5: Infusion Date | BF5: Fixed Charges (₹) | BG5: Consumable (₹) | BH5: Nursing (₹) | BI5: Carcinome (₹) | BJ5: Total Charges (₹) | BK5: Total Received (₹) | BL5: Balance (₹) | BM5: Payment Status | BN5: Service | BO5: Infusion Date | BP5: Fixed Charges (₹) | BQ5: Consumable (₹) | BR5: Nursing (₹) | BS5: Carcinome (₹) | BT5: Total Charges (₹) | BU5: Total Received (₹) | BV5: Balance (₹) | BW5: Payment Status | BX5: Service | BY5: Infusion Date | BZ5: Fixed Charges (₹) | CA5: Consumable (₹) | CB5: Nursing (₹) | CC5: Carcinome (₹) | CD5: Total Charges (₹) | CE5: Total Received (₹) | CF5: Balance (₹) | CG5: Payment Status | CH5: Service | CI5: Infusion Date | CJ5: Fixed Charges (₹) | CK5: Consumable (₹) | CL5: Nursing (₹) | CM5: Carcinome (₹) | CN5: Total Charges (₹) | CO5: Total Received (₹) | CP5: Balance (₹) | CQ5: Payment Status | CR5: Service | CS5: Infusion Date | CT5: Fixed Charges (₹) | CU5: Consumable (₹) | CV5: Nursing (₹) | CW5: Carcinome (₹) | CX5: Total Charges (₹) | CY5: Total Received (₹) | CZ5: Balance (₹) | DA5: Payment Status | DB5: Service | DC5: Infusion Date | DD5: Fixed Charges (₹) | DE5: Consumable (₹) | DF5: Nursing (₹) | DG5: Carcinome (₹) | DH5: Total Charges (₹) | DI5: Total Received (₹) | DJ5: Balance (₹) | DK5: Payment Status | DL5: Service | DM5: Infusion Date | DN5: Fixed Charges (₹) | DO5: Consumable (₹) | DP5: Nursing (₹) | DQ5: Carcinome (₹) | DR5: Total Charges (₹) | DS5: Total Received (₹) | DT5: Balance (₹) | DU5: Payment Status | DV5: Service | DW5: Infusion Date | DX5: Fixed Charges (₹) | DY5: Consumable (₹) | DZ5: Nursing (₹) | EA5: Carcinome (₹) | EB5: Total Charges (₹) | EC5: Total Received (₹) | ED5: Balance (₹) | EE5: Payment Status | EF5: Service | EG5: Infusion Date | EH5: Fixed Charges (₹) | EI5: Consumable (₹) | EJ5: Nursing (₹) | EK5: Carcinome (₹) | EL5: Total Charges (₹) | EM5: Total Received (₹) | EN5: Balance (₹) | EO5: Payment Status | EP5: Service | EQ5: Infusion Date | ER5: Fixed Charges (₹) | ES5: Consumable (₹) | ET5: Nursing (₹) | EU5: Carcinome (₹) | EV5: Total Charges (₹) | EW5: Total Received (₹) | EX5: Balance (₹) | EY5: Payment Status | EZ5: Service | FA5: Infusion Date | FB5: Fixed Charges (₹) | FC5: Consumable (₹) | FD5: Nursing (₹) | FE5: Carcinome (₹) | FF5: Total Charges (₹) | FG5: Total Received (₹) | FH5: Balance (₹) | FI5: Payment Status | FJ5: Service | FK5: Infusion Date | FL5: Fixed Charges (₹) | FM5: Consumable (₹) | FN5: Nursing (₹) | FO5: Carcinome (₹) | FP5: Total Charges (₹) | FQ5: Total Received (₹) | FR5: Balance (₹) | FS5: Payment Status
A6: CC2026001 | B6: Pappu | C6: VIJAY | D6: 99340 38365 | E6: so the treatment is over all bills paid | G6: 2026-07-21 | H6: 0 | I6: =IF($A6="","",SUMIFS('Consumable Usage'!$E:$E,'Consumable Usage'!$A:$A,$A6,'Consumable Usage'!$D:$D,1)) -> 0 | J6: =IF($A6="","",SUMIFS('Nursing Charges'!$I:$I,'Nursing Charges'!$A:$A,$A6,'Nursing Charges'!$C:$C,1)) -> 5400 | K6: =IF($A6="","",H6+(J6-SUMIFS('Nursing Charges'!$J:$J,'Nursing Charges'!$A:$A,$A6,'Nursing Charges'!$C:$C,1))+(I6-SUMIFS('Consumable Usage'!$F:$F,'Consumable Usage'!$A:$A,$A6,'Consumable Usage'!$D:$D,1))) -> 5400 | L6: =IF($A6="","",H6+J6+I6) -> 5400 | N6: =IF(L6="","",L6-M6) -> 5400 | O6: =IF(OR($A6="",F6=""),"",IF(L6=0,"No Charges",IF(N6<=0,"Paid",IF(M6>0,"Partial","Pending")))) | P6: Chemo Infusion | Q6: 2026-07-29 | R6: 0 | S6: =IF($A6="","",SUMIFS('Consumable Usage'!$E:$E,'Consumable Usage'!$A:$A,$A6,'Consumable Usage'!$D:$D,2)) -> 0 | T6: =IF($A6="","",SUMIFS('Nursing Charges'!$I:$I,'Nursing Charges'!$A:$A,$A6,'Nursing Charges'!$C:$C,2)) -> 0 | U6: =IF($A6="","",R6+(T6-SUMIFS('Nursing Charges'!$J:$J,'Nursing Charges'!$A:$A,$A6,'Nursing Charges'!$C:$C,2))+(S6-SUMIFS('Consumable Usage'!$F:$F,'Consumable Usage'!$A:$A,$A6,'Consumable Usage'!$D:$D,2))) -> 0 | V6: =IF($A6="","",R6+T6+S6) -> 0 | X6: =IF(V6="","",V6-W6) -> 0 | Y6: =IF(OR($A6="",P6=""),"",IF(V6=0,"No Charges",IF(X6<=0,"Paid",IF(W6>0,"Partial","Pending")))) -> No Charges | AC6: =IF($A6="","",SUMIFS('Consumable Usage'!$E:$E,'Consumable Usage'!$A:$A,$A6,'Consumable Usage'!$D:$D,3)) -> 0 | AD6: =IF($A6="","",SUMIFS('Nursing Charges'!$I:$I,'Nursing Charges'!$A:$A,$A6,'Nursing Charges'!$C:$C,3)) -> 0 | AE6: =IF($A6="","",AB6+(AD6-SUMIFS('Nursing Charges'!$J:$J,'Nursing Charges'!$A:$A,$A6,'Nursing Charges'!$C:$C,3))+(AC6-SUMIFS('Consumable Usage'!$F:$F,'Consumable Usage'!$A:$A,$A6,'Consumable Usage'!$D:$D,3))) -> 0 | AF6: =IF($A6="","",AB6+AD6+AC6) -> 0 | AH6: =IF(AF6="","",AF6-AG6) -> 0 | AI6: =IF(OR($A6="",Z6=""),"",IF(AF6=0,"No Charges",IF(AH6<=0,"Paid",IF(AG6>0,"Partial","Pending")))) | AM6: =IF($A6="","",SUMIFS('Consumable Usage'!$E:$E,'Consumable Usage'!$A:$A,$A6,'Consumable Usage'!$D:$D,4)) -> 0 | AN6: =IF($A6="","",SUMIFS('Nursing Charges'!$I:$I,'Nursing Charges'!$A:$A,$A6,'Nursing Charges'!$C:$C,4)) -> 0 | AO6: =IF($A6="","",AL6+(AN6-SUMIFS('Nursing Charges'!$J:$J,'Nursing Charges'!$A:$A,$A6,'Nursing Charges'!$C:$C,4))+(AM6-SUMIFS('Consumable Usage'!$F:$F,'Consumable Usage'!$A:$A,$A6,'Consumable Usage'!$D:$D,4))) -> 0 | AP6: =IF($A6="","",AL6+AN6+AM6) -> 0 | AR6: =IF(AP6="","",AP6-AQ6) -> 0 | AS6: =IF(OR($A6="",AJ6=""),"",IF(AP6=0,"No Charges",IF(AR6<=0,"Paid",IF(AQ6>0,"Partial","Pending")))) | AW6: =IF($A6="","",SUMIFS('Consumable Usage'!$E:$E,'Consumable Usage'!$A:$A,$A6,'Consumable Usage'!$D:$D,5)) -> 0 | AX6: =IF($A6="","",SUMIFS('Nursing Charges'!$I:$I,'Nursing Charges'!$A:$A,$A6,'Nursing Charges'!$C:$C,5)) -> 0 | AY6: =IF($A6="","",AV6+(AX6-SUMIFS('Nursing Charges'!$J:$J,'Nursing Charges'!$A:$A,$A6,'Nursing Charges'!$C:$C,5))+(AW6-SUMIFS('Consumable Usage'!$F:$F,'Consumable Usage'!$A:$A,$A6,'Consumable Usage'!$D:$D,5))) -> 0 | AZ6: =IF($A6="","",AV6+AX6+AW6) -> 0 | BB6: =IF(AZ6="","",AZ6-BA6) -> 0 | BC6: =IF(OR($A6="",AT6=""),"",IF(AZ6=0,"No Charges",IF(BB6<=0,"Paid",IF(BA6>0,"Partial","Pending")))) | BG6: =IF($A6="","",SUMIFS('Consumable Usage'!$E:$E,'Consumable Usage'!$A:$A,$A6,'Consumable Usage'!$D:$D,6)) -> 850 | BH6: =IF($A6="","",SUMIFS('Nursing Charges'!$I:$I,'Nursing Charges'!$A:$A,$A6,'Nursing Charges'!$C:$C,6)) -> 0 | BI6: =IF($A6="","",BF6+(BH6-SUMIFS('Nursing Charges'!$J:$J,'Nursing Charges'!$A:$A,$A6,'Nursing Charges'!$C:$C,6))+(BG6-SUMIFS('Consumable Usage'!$F:$F,'Consumable Usage'!$A:$A,$A6,'Consumable Usage'!$D:$D,6))) -> 330 | BJ6: =IF($A6="","",BF6+BH6+BG6) -> 850 | BL6: =IF(BJ6="","",BJ6-BK6) -> 850 | BM6: =IF(OR($A6="",BD6=""),"",IF(BJ6=0,"No Charges",IF(BL6<=0,"Paid",IF(BK6>0,"Partial","Pending")))) | BQ6: =IF($A6="","",SUMIFS('Consumable Usage'!$E:$E,'Consumable Usage'!$A:$A,$A6,'Consumable Usage'!$D:$D,7)) -> 0 | BR6: =IF($A6="","",SUMIFS('Nursing Charges'!$I:$I,'Nursing Charges'!$A:$A,$A6,'Nursing Charges'!$C:$C,7)) -> 0 | BS6: =IF($A6="","",BP6+(BR6-SUMIFS('Nursing Charges'!$J:$J,'Nursing Charges'!$A:$A,$A6,'Nursing Charges'!$C:$C,7))+(BQ6-SUMIFS('Consumable Usage'!$F:$F,'Consumable Usage'!$A:$A,$A6,'Consumable Usage'!$D:$D,7))) -> 0 | BT6: =IF($A6="","",BP6+BR6+BQ6) -> 0 | BV6: =IF(BT6="","",BT6-BU6) -> 0 | BW6: =IF(OR($A6="",BN6=""),"",IF(BT6=0,"No Charges",IF(BV6<=0,"Paid",IF(BU6>0,"Partial","Pending")))) | CA6: =IF($A6="","",SUMIFS('Consumable Usage'!$E:$E,'Consumable Usage'!$A:$A,$A6,'Consumable Usage'!$D:$D,8)) -> 0 | CB6: =IF($A6="","",SUMIFS('Nursing Charges'!$I:$I,'Nursing Charges'!$A:$A,$A6,'Nursing Charges'!$C:$C,8)) -> 0 | CC6: =IF($A6="","",BZ6+(CB6-SUMIFS('Nursing Charges'!$J:$J,'Nursing Charges'!$A:$A,$A6,'Nursing Charges'!$C:$C,8))+(CA6-SUMIFS('Consumable Usage'!$F:$F,'Consumable Usage'!$A:$A,$A6,'Consumable Usage'!$D:$D,8))) -> 0 | CD6: =IF($A6="","",BZ6+CB6+CA6) -> 0 | CF6: =IF(CD6="","",CD6-CE6) -> 0 | CG6: =IF(OR($A6="",BX6=""),"",IF(CD6=0,"No Charges",IF(CF6<=0,"Paid",IF(CE6>0,"Partial","Pending")))) | CK6: =IF($A6="","",SUMIFS('Consumable Usage'!$E:$E,'Consumable Usage'!$A:$A,$A6,'Consumable Usage'!$D:$D,9)) -> 0 | CL6: =IF($A6="","",SUMIFS('Nursing Charges'!$I:$I,'Nursing Charges'!$A:$A,$A6,'Nursing Charges'!$C:$C,9)) -> 0 | CM6: =IF($A6="","",CJ6+(CL6-SUMIFS('Nursing Charges'!$J:$J,'Nursing Charges'!$A:$A,$A6,'Nursing Charges'!$C:$C,9))+(CK6-SUMIFS('Consumable Usage'!$F:$F,'Consumable Usage'!$A:$A,$A6,'Consumable Usage'!$D:$D,9))) -> 0 | CN6: =IF($A6="","",CJ6+CL6+CK6) -> 0 | CP6: =IF(CN6="","",CN6-CO6) -> 0 | CQ6: =IF(OR($A6="",CH6=""),"",IF(CN6=0,"No Charges",IF(CP6<=0,"Paid",IF(CO6>0,"Partial","Pending")))) | CU6: =IF($A6="","",SUMIFS('Consumable Usage'!$E:$E,'Consumable Usage'!$A:$A,$A6,'Consumable Usage'!$D:$D,10)) -> 0 | CV6: =IF($A6="","",SUMIFS('Nursing Charges'!$I:$I,'Nursing Charges'!$A:$A,$A6,'Nursing Charges'!$C:$C,10)) -> 0 | CW6: =IF($A6="","",CT6+(CV6-SUMIFS('Nursing Charges'!$J:$J,'Nursing Charges'!$A:$A,$A6,'Nursing Charges'!$C:$C,10))+(CU6-SUMIFS('Consumable Usage'!$F:$F,'Consumable Usage'!$A:$A,$A6,'Consumable Usage'!$D:$D,10))) -> 0 | CX6: =IF($A6="","",CT6+CV6+CU6) -> 0 | CZ6: =IF(CX6="","",CX6-CY6) -> 0 | DA6: =IF(OR($A6="",CR6=""),"",IF(CX6=0,"No Charges",IF(CZ6<=0,"Paid",IF(CY6>0,"Partial","Pending")))) | DE6: =IF($A6="","",SUMIFS('Consumable Usage'!$E:$E,'Consumable Usage'!$A:$A,$A6,'Consumable Usage'!$D:$D,11)) -> 0 | DF6: =IF($A6="","",SUMIFS('Nursing Charges'!$I:$I,'Nursing Charges'!$A:$A,$A6,'Nursing Charges'!$C:$C,11)) -> 0 | DG6: =IF($A6="","",DD6+(DF6-SUMIFS('Nursing Charges'!$J:$J,'Nursing Charges'!$A:$A,$A6,'Nursing Charges'!$C:$C,11))+(DE6-SUMIFS('Consumable Usage'!$F:$F,'Consumable Usage'!$A:$A,$A6,'Consumable Usage'!$D:$D,11))) -> 0 | DH6: =IF($A6="","",DD6+DF6+DE6) -> 0 | DJ6: =IF(DH6="","",DH6-DI6) -> 0 | DK6: =IF(OR($A6="",DB6=""),"",IF(DH6=0,"No Charges",IF(DJ6<=0,"Paid",IF(DI6>0,"Partial","Pending")))) | DO6: =IF($A6="","",SUMIFS('Consumable Usage'!$E:$E,'Consumable Usage'!$A:$A,$A6,'Consumable Usage'!$D:$D,12)) -> 0 | DP6: =IF($A6="","",SUMIFS('Nursing Charges'!$I:$I,'Nursing Charges'!$A:$A,$A6,'Nursing Charges'!$C:$C,12)) -> 0 | DQ6: =IF($A6="","",DN6+(DP6-SUMIFS('Nursing Charges'!$J:$J,'Nursing Charges'!$A:$A,$A6,'Nursing Charges'!$C:$C,12))+(DO6-SUMIFS('Consumable Usage'!$F:$F,'Consumable Usage'!$A:$A,$A6,'Consumable Usage'!$D:$D,12))) -> 0 | DR6: =IF($A6="","",DN6+DP6+DO6) -> 0 | DT6: =IF(DR6="","",DR6-DS6) -> 0 | DU6: =IF(OR($A6="",DL6=""),"",IF(DR6=0,"No Charges",IF(DT6<=0,"Paid",IF(DS6>0,"Partial","Pending")))) | DY6: =IF($A6="","",SUMIFS('Consumable Usage'!$E:$E,'Consumable Usage'!$A:$A,$A6,'Consumable Usage'!$D:$D,13)) -> 0 | DZ6: =IF($A6="","",SUMIFS('Nursing Charges'!$I:$I,'Nursing Charges'!$A:$A,$A6,'Nursing Charges'!$C:$C,13)) -> 0 | EA6: =IF($A6="","",DX6+(DZ6-SUMIFS('Nursing Charges'!$J:$J,'Nursing Charges'!$A:$A,$A6,'Nursing Charges'!$C:$C,13))+(DY6-SUMIFS('Consumable Usage'!$F:$F,'Consumable Usage'!$A:$A,$A6,'Consumable Usage'!$D:$D,13))) -> 0 | EB6: =IF($A6="","",DX6+DZ6+DY6) -> 0 | ED6: =IF(EB6="","",EB6-EC6) -> 0 | EE6: =IF(OR($A6="",DV6=""),"",IF(EB6=0,"No Charges",IF(ED6<=0,"Paid",IF(EC6>0,"Partial","Pending")))) | EI6: =IF($A6="","",SUMIFS('Consumable Usage'!$E:$E,'Consumable Usage'!$A:$A,$A6,'Consumable Usage'!$D:$D,14)) -> 0 | EJ6: =IF($A6="","",SUMIFS('Nursing Charges'!$I:$I,'Nursing Charges'!$A:$A,$A6,'Nursing Charges'!$C:$C,14)) -> 0 | EK6: =IF($A6="","",EH6+(EJ6-SUMIFS('Nursing Charges'!$J:$J,'Nursing Charges'!$A:$A,$A6,'Nursing Charges'!$C:$C,14))+(EI6-SUMIFS('Consumable Usage'!$F:$F,'Consumable Usage'!$A:$A,$A6,'Consumable Usage'!$D:$D,14))) -> 0 | EL6: =IF($A6="","",EH6+EJ6+EI6) -> 0 | EN6: =IF(EL6="","",EL6-EM6) -> 0 | EO6: =IF(OR($A6="",EF6=""),"",IF(EL6=0,"No Charges",IF(EN6<=0,"Paid",IF(EM6>0,"Partial","Pending")))) | ES6: =IF($A6="","",SUMIFS('Consumable Usage'!$E:$E,'Consumable Usage'!$A:$A,$A6,'Consumable Usage'!$D:$D,15)) -> 0 | ET6: =IF($A6="","",SUMIFS('Nursing Charges'!$I:$I,'Nursing Charges'!$A:$A,$A6,'Nursing Charges'!$C:$C,15)) -> 0 | EU6: =IF($A6="","",ER6+(ET6-SUMIFS('Nursing Charges'!$J:$J,'Nursing Charges'!$A:$A,$A6,'Nursing Charges'!$C:$C,15))+(ES6-SUMIFS('Consumable Usage'!$F:$F,'Consumable Usage'!$A:$A,$A6,'Consumable Usage'!$D:$D,15))) -> 0 | EV6: =IF($A6="","",ER6+ET6+ES6) -> 0 | EX6: =IF(EV6="","",EV6-EW6) -> 0 | EY6: =IF(OR($A6="",EP6=""),"",IF(EV6=0,"No Charges",IF(EX6<=0,"Paid",IF(EW6>0,"Partial","Pending")))) | FC6: =IF($A6="","",SUMIFS('Consumable Usage'!$E:$E,'Consumable Usage'!$A:$A,$A6,'Consumable Usage'!$D:$D,16)) -> 0 | FD6: =IF($A6="","",SUMIFS('Nursing Charges'!$I:$I,'Nursing Charges'!$A:$A,$A6,'Nursing Charges'!$C:$C,16)) -> 0 | FE6: =IF($A6="","",FB6+(FD6-SUMIFS('Nursing Charges'!$J:$J,'Nursing Charges'!$A:$A,$A6,'Nursing Charges'!$C:$C,16))+(FC6-SUMIFS('Consumable Usage'!$F:$F,'Consumable Usage'!$A:$A,$A6,'Consumable Usage'!$D:$D,16))) -> 0 | FF6: =IF($A6="","",FB6+FD6+FC6) -> 0 | FH6: =IF(FF6="","",FF6-FG6) -> 0 | FI6: =IF(OR($A6="",EZ6=""),"",IF(FF6=0,"No Charges",IF(FH6<=0,"Paid",IF(FG6>0,"Partial","Pending")))) | FM6: =IF($A6="","",SUMIFS('Consumable Usage'!$E:$E,'Consumable Usage'!$A:$A,$A6,'Consumable Usage'!$D:$D,16)) -> 0 | FN6: =IF($A6="","",SUMIFS('Nursing Charges'!$I:$I,'Nursing Charges'!$A:$A,$A6,'Nursing Charges'!$C:$C,16)) -> 0 | FO6: =IF($A6="","",FL6+(FN6-SUMIFS('Nursing Charges'!$J:$J,'Nursing Charges'!$A:$A,$A6,'Nursing Charges'!$C:$C,16))+(FM6-SUMIFS('Consumable Usage'!$F:$F,'Consumable Usage'!$A:$A,$A6,'Consumable Usage'!$D:$D,16))) -> 0 | FP6: =IF($A6="","",FL6+FN6+FM6) -> 0 | FR6: =IF(FP6="","",FP6-FQ6) -> 0 | FS6: =IF(OR($A6="",FJ6=""),"",IF(FP6=0,"No Charges",IF(FR6<=0,"Paid",IF(FQ6>0,"Partial","Pending"))))
A7: CC2026002 | B7: Pushpa Ram Bachani | C7: SOUMYA AND TANYA | D7: 98338 63777 : Divesh Bachani | E7: need to create bill for 19th and 25th | G7: 2026-07-19 | H7: 0 | I7: =IF($A7="","",SUMIFS('Consumable Usage'!$E:$E,'Consumable Usage'!$A:$A,$A7,'Consumable Usage'!$D:$D,1)) -> 0 | J7: =IF($A7="","",SUMIFS('Nursing Charges'!$I:$I,'Nursing Charges'!$A:$A,$A7,'Nursing Charges'!$C:$C,1)) -> 0 | K7: =IF($A7="","",H7+(J7-SUMIFS('Nursing Charges'!$J:$J,'Nursing Charges'!$A:$A,$A7,'Nursing Charges'!$C:$C,1))+(I7-SUMIFS('Consumable Usage'!$F:$F,'Consumable Usage'!$A:$A,$A7,'Consumable Usage'!$D:$D,1))) -> 0 | L7: =IF($A7="","",H7+J7+I7) -> 0 | M7: 0 | N7: =IF(L7="","",L7-M7) -> 0 | O7: =IF(OR($A7="",F7=""),"",IF(L7=0,"No Charges",IF(N7<=0,"Paid",IF(M7>0,"Partial","Pending")))) | P7: Chemo Infusion | Q7: 2026-07-25 | R7: 0 | S7: =IF($A7="","",SUMIFS('Consumable Usage'!$E:$E,'Consumable Usage'!$A:$A,$A7,'Consumable Usage'!$D:$D,2)) -> 0 | T7: =IF($A7="","",SUMIFS('Nursing Charges'!$I:$I,'Nursing Charges'!$A:$A,$A7,'Nursing Charges'!$C:$C,2)) -> 0 | U7: =IF($A7="","",R7+(T7-SUMIFS('Nursing Charges'!$J:$J,'Nursing Charges'!$A:$A,$A7,'Nursing Charges'!$C:$C,2))+(S7-SUMIFS('Consumable Usage'!$F:$F,'Consumable Usage'!$A:$A,$A7,'Consumable Usage'!$D:$D,2))) -> 0 | V7: =IF($A7="","",R7+T7+S7) -> 0 | W7: 0 | X7: =IF(V7="","",V7-W7) -> 0 | Y7: =IF(OR($A7="",P7=""),"",IF(V7=0,"No Charges",IF(X7<=0,"Paid",IF(W7>0,"Partial","Pending")))) -> No Charges | AC7: =IF($A7="","",SUMIFS('Consumable Usage'!$E:$E,'Consumable Usage'!$A:$A,$A7,'Consumable Usage'!$D:$D,3)) -> 0 | AD7: =IF($A7="","",SUMIFS('Nursing Charges'!$I:$I,'Nursing Charges'!$A:$A,$A7,'Nursing Charges'!$C:$C,3)) -> 0 | AE7: =IF($A7="","",AB7+(AD7-SUMIFS('Nursing Charges'!$J:$J,'Nursing Charges'!$A:$A,$A7,'Nursing Charges'!$C:$C,3))+(AC7-SUMIFS('Consumable Usage'!$F:$F,'Consumable Usage'!$A:$A,$A7,'Consumable Usage'!$D:$D,3))) -> 0 | AF7: =IF($A7="","",AB7+AD7+AC7) -> 0 | AH7: =IF(AF7="","",AF7-AG7) -> 0 | AI7: =IF(OR($A7="",Z7=""),"",IF(AF7=0,"No Charges",IF(AH7<=0,"Paid",IF(AG7>0,"Partial","Pending")))) | AM7: =IF($A7="","",SUMIFS('Consumable Usage'!$E:$E,'Consumable Usage'!$A:$A,$A7,'Consumable Usage'!$D:$D,4)) -> 0 | AN7: =IF($A7="","",SUMIFS('Nursing Charges'!$I:$I,'Nursing Charges'!$A:$A,$A7,'Nursing Charges'!$C:$C,4)) -> 0 | AO7: =IF($A7="","",AL7+(AN7-SUMIFS('Nursing Charges'!$J:$J,'Nursing Charges'!$A:$A,$A7,'Nursing Charges'!$C:$C,4))+(AM7-SUMIFS('Consumable Usage'!$F:$F,'Consumable Usage'!$A:$A,$A7,'Consumable Usage'!$D:$D,4))) -> 0 | AP7: =IF($A7="","",AL7+AN7+AM7) -> 0 | AR7: =IF(AP7="","",AP7-AQ7) -> 0 | AS7: =IF(OR($A7="",AJ7=""),"",IF(AP7=0,"No Charges",IF(AR7<=0,"Paid",IF(AQ7>0,"Partial","Pending")))) | AW7: =IF($A7="","",SUMIFS('Consumable Usage'!$E:$E,'Consumable Usage'!$A:$A,$A7,'Consumable Usage'!$D:$D,5)) -> 0 | AX7: =IF($A7="","",SUMIFS('Nursing Charges'!$I:$I,'Nursing Charges'!$A:$A,$A7,'Nursing Charges'!$C:$C,5)) -> 0 | AY7: =IF($A7="","",AV7+(AX7-SUMIFS('Nursing Charges'!$J:$J,'Nursing Charges'!$A:$A,$A7,'Nursing Charges'!$C:$C,5))+(AW7-SUMIFS('Consumable Usage'!$F:$F,'Consumable Usage'!$A:$A,$A7,'Consumable Usage'!$D:$D,5))) -> 0 | AZ7: =IF($A7="","",AV7+AX7+AW7) -> 0 | BB7: =IF(AZ7="","",AZ7-BA7) -> 0 | BC7: =IF(OR($A7="",AT7=""),"",IF(AZ7=0,"No Charges",IF(BB7<=0,"Paid",IF(BA7>0,"Partial","Pending")))) | BG7: =IF($A7="","",SUMIFS('Consumable Usage'!$E:$E,'Consumable Usage'!$A:$A,$A7,'Consumable Usage'!$D:$D,6)) -> 0 | BH7: =IF($A7="","",SUMIFS('Nursing Charges'!$I:$I,'Nursing Charges'!$A:$A,$A7,'Nursing Charges'!$C:$C,6)) -> 0 | BI7: =IF($A7="","",BF7+(BH7-SUMIFS('Nursing Charges'!$J:$J,'Nursing Charges'!$A:$A,$A7,'Nursing Charges'!$C:$C,6))+(BG7-SUMIFS('Consumable Usage'!$F:$F,'Consumable Usage'!$A:$A,$A7,'Consumable Usage'!$D:$D,6))) -> 0 | BJ7: =IF($A7="","",BF7+BH7+BG7) -> 0 | BL7: =IF(BJ7="","",BJ7-BK7) -> 0 | BM7: =IF(OR($A7="",BD7=""),"",IF(BJ7=0,"No Charges",IF(BL7<=0,"Paid",IF(BK7>0,"Partial","Pending")))) | BQ7: =IF($A7="","",SUMIFS('Consumable Usage'!$E:$E,'Consumable Usage'!$A:$A,$A7,'Consumable Usage'!$D:$D,7)) -> 0 | BR7: =IF($A7="","",SUMIFS('Nursing Charges'!$I:$I,'Nursing Charges'!$A:$A,$A7,'Nursing Charges'!$C:$C,7)) -> 0 | BS7: =IF($A7="","",BP7+(BR7-SUMIFS('Nursing Charges'!$J:$J,'Nursing Charges'!$A:$A,$A7,'Nursing Charges'!$C:$C,7))+(BQ7-SUMIFS('Consumable Usage'!$F:$F,'Consumable Usage'!$A:$A,$A7,'Consumable Usage'!$D:$D,7))) -> 0 | BT7: =IF($A7="","",BP7+BR7+BQ7) -> 0 | BV7: =IF(BT7="","",BT7-BU7) -> 0 | BW7: =IF(OR($A7="",BN7=""),"",IF(BT7=0,"No Charges",IF(BV7<=0,"Paid",IF(BU7>0,"Partial","Pending")))) | CA7: =IF($A7="","",SUMIFS('Consumable Usage'!$E:$E,'Consumable Usage'!$A:$A,$A7,'Consumable Usage'!$D:$D,8)) -> 0 | CB7: =IF($A7="","",SUMIFS('Nursing Charges'!$I:$I,'Nursing Charges'!$A:$A,$A7,'Nursing Charges'!$C:$C,8)) -> 0 | CC7: =IF($A7="","",BZ7+(CB7-SUMIFS('Nursing Charges'!$J:$J,'Nursing Charges'!$A:$A,$A7,'Nursing Charges'!$C:$C,8))+(CA7-SUMIFS('Consumable Usage'!$F:$F,'Consumable Usage'!$A:$A,$A7,'Consumable Usage'!$D:$D,8))) -> 0 | CD7: =IF($A7="","",BZ7+CB7+CA7) -> 0 | CF7: =IF(CD7="","",CD7-CE7) -> 0 | CG7: =IF(OR($A7="",BX7=""),"",IF(CD7=0,"No Charges",IF(CF7<=0,"Paid",IF(CE7>0,"Partial","Pending")))) | CK7: =IF($A7="","",SUMIFS('Consumable Usage'!$E:$E,'Consumable Usage'!$A:$A,$A7,'Consumable Usage'!$D:$D,9)) -> 0 | CL7: =IF($A7="","",SUMIFS('Nursing Charges'!$I:$I,'Nursing Charges'!$A:$A,$A7,'Nursing Charges'!$C:$C,9)) -> 0 | CM7: =IF($A7="","",CJ7+(CL7-SUMIFS('Nursing Charges'!$J:$J,'Nursing Charges'!$A:$A,$A7,'Nursing Charges'!$C:$C,9))+(CK7-SUMIFS('Consumable Usage'!$F:$F,'Consumable Usage'!$A:$A,$A7,'Consumable Usage'!$D:$D,9))) -> 0 | CN7: =IF($A7="","",CJ7+CL7+CK7) -> 0 | CP7: =IF(CN7="","",CN7-CO7) -> 0 | CQ7: =IF(OR($A7="",CH7=""),"",IF(CN7=0,"No Charges",IF(CP7<=0,"Paid",IF(CO7>0,"Partial","Pending")))) | CU7: =IF($A7="","",SUMIFS('Consumable Usage'!$E:$E,'Consumable Usage'!$A:$A,$A7,'Consumable Usage'!$D:$D,10)) -> 0 | CV7: =IF($A7="","",SUMIFS('Nursing Charges'!$I:$I,'Nursing Charges'!$A:$A,$A7,'Nursing Charges'!$C:$C,10)) -> 0 | CW7: =IF($A7="","",CT7+(CV7-SUMIFS('Nursing Charges'!$J:$J,'Nursing Charges'!$A:$A,$A7,'Nursing Charges'!$C:$C,10))+(CU7-SUMIFS('Consumable Usage'!$F:$F,'Consumable Usage'!$A:$A,$A7,'Consumable Usage'!$D:$D,10))) -> 0 | CX7: =IF($A7="","",CT7+CV7+CU7) -> 0 | CZ7: =IF(CX7="","",CX7-CY7) -> 0 | DA7: =IF(OR($A7="",CR7=""),"",IF(CX7=0,"No Charges",IF(CZ7<=0,"Paid",IF(CY7>0,"Partial","Pending")))) | DE7: =IF($A7="","",SUMIFS('Consumable Usage'!$E:$E,'Consumable Usage'!$A:$A,$A7,'Consumable Usage'!$D:$D,11)) -> 0 | DF7: =IF($A7="","",SUMIFS('Nursing Charges'!$I:$I,'Nursing Charges'!$A:$A,$A7,'Nursing Charges'!$C:$C,11)) -> 0 | DG7: =IF($A7="","",DD7+(DF7-SUMIFS('Nursing Charges'!$J:$J,'Nursing Charges'!$A:$A,$A7,'Nursing Charges'!$C:$C,11))+(DE7-SUMIFS('Consumable Usage'!$F:$F,'Consumable Usage'!$A:$A,$A7,'Consumable Usage'!$D:$D,11))) -> 0 | DH7: =IF($A7="","",DD7+DF7+DE7) -> 0 | DJ7: =IF(DH7="","",DH7-DI7) -> 0 | DK7: =IF(OR($A7="",DB7=""),"",IF(DH7=0,"No Charges",IF(DJ7<=0,"Paid",IF(DI7>0,"Partial","Pending")))) | DO7: =IF($A7="","",SUMIFS('Consumable Usage'!$E:$E,'Consumable Usage'!$A:$A,$A7,'Consumable Usage'!$D:$D,12)) -> 0 | DP7: =IF($A7="","",SUMIFS('Nursing Charges'!$I:$I,'Nursing Charges'!$A:$A,$A7,'Nursing Charges'!$C:$C,12)) -> 0 | DQ7: =IF($A7="","",DN7+(DP7-SUMIFS('Nursing Charges'!$J:$J,'Nursing Charges'!$A:$A,$A7,'Nursing Charges'!$C:$C,12))+(DO7-SUMIFS('Consumable Usage'!$F:$F,'Consumable Usage'!$A:$A,$A7,'Consumable Usage'!$D:$D,12))) -> 0 | DR7: =IF($A7="","",DN7+DP7+DO7) -> 0 | DT7: =IF(DR7="","",DR7-DS7) -> 0 | DU7: =IF(OR($A7="",DL7=""),"",IF(DR7=0,"No Charges",IF(DT7<=0,"Paid",IF(DS7>0,"Partial","Pending")))) | DY7: =IF($A7="","",SUMIFS('Consumable Usage'!$E:$E,'Consumable Usage'!$A:$A,$A7,'Consumable Usage'!$D:$D,13)) -> 0 | DZ7: =IF($A7="","",SUMIFS('Nursing Charges'!$I:$I,'Nursing Charges'!$A:$A,$A7,'Nursing Charges'!$C:$C,13)) -> 0 | EA7: =IF($A7="","",DX7+(DZ7-SUMIFS('Nursing Charges'!$J:$J,'Nursing Charges'!$A:$A,$A7,'Nursing Charges'!$C:$C,13))+(DY7-SUMIFS('Consumable Usage'!$F:$F,'Consumable Usage'!$A:$A,$A7,'Consumable Usage'!$D:$D,13))) -> 0 | EB7: =IF($A7="","",DX7+DZ7+DY7) -> 0 | ED7: =IF(EB7="","",EB7-EC7) -> 0 | EE7: =IF(OR($A7="",DV7=""),"",IF(EB7=0,"No Charges",IF(ED7<=0,"Paid",IF(EC7>0,"Partial","Pending")))) | EI7: =IF($A7="","",SUMIFS('Consumable Usage'!$E:$E,'Consumable Usage'!$A:$A,$A7,'Consumable Usage'!$D:$D,14)) -> 0 | EJ7: =IF($A7="","",SUMIFS('Nursing Charges'!$I:$I,'Nursing Charges'!$A:$A,$A7,'Nursing Charges'!$C:$C,14)) -> 0 | EK7: =IF($A7="","",EH7+(EJ7-SUMIFS('Nursing Charges'!$J:$J,'Nursing Charges'!$A:$A,$A7,'Nursing Charges'!$C:$C,14))+(EI7-SUMIFS('Consumable Usage'!$F:$F,'Consumable Usage'!$A:$A,$A7,'Consumable Usage'!$D:$D,14))) -> 0 | EL7: =IF($A7="","",EH7+EJ7+EI7) -> 0 | EN7: =IF(EL7="","",EL7-EM7) -> 0 | EO7: =IF(OR($A7="",EF7=""),"",IF(EL7=0,"No Charges",IF(EN7<=0,"Paid",IF(EM7>0,"Partial","Pending")))) | ES7: =IF($A7="","",SUMIFS('Consumable Usage'!$E:$E,'Consumable Usage'!$A:$A,$A7,'Consumable Usage'!$D:$D,15)) -> 0 | ET7: =IF($A7="","",SUMIFS('Nursing Charges'!$I:$I,'Nursing Charges'!$A:$A,$A7,'Nursing Charges'!$C:$C,15)) -> 0 | EU7: =IF($A7="","",ER7+(ET7-SUMIFS('Nursing Charges'!$J:$J,'Nursing Charges'!$A:$A,$A7,'Nursing Charges'!$C:$C,15))+(ES7-SUMIFS('Consumable Usage'!$F:$F,'Consumable Usage'!$A:$A,$A7,'Consumable Usage'!$D:$D,15))) -> 0 | EV7: =IF($A7="","",ER7+ET7+ES7) -> 0 | EX7: =IF(EV7="","",EV7-EW7) -> 0 | EY7: =IF(OR($A7="",EP7=""),"",IF(EV7=0,"No Charges",IF(EX7<=0,"Paid",IF(EW7>0,"Partial","Pending")))) | FC7: =IF($A7="","",SUMIFS('Consumable Usage'!$E:$E,'Consumable Usage'!$A:$A,$A7,'Consumable Usage'!$D:$D,16)) -> 0 | FD7: =IF($A7="","",SUMIFS('Nursing Charges'!$I:$I,'Nursing Charges'!$A:$A,$A7,'Nursing Charges'!$C:$C,16)) -> 0 | FE7: =IF($A7="","",FB7+(FD7-SUMIFS('Nursing Charges'!$J:$J,'Nursing Charges'!$A:$A,$A7,'Nursing Charges'!$C:$C,16))+(FC7-SUMIFS('Consumable Usage'!$F:$F,'Consumable Usage'!$A:$A,$A7,'Consumable Usage'!$D:$D,16))) -> 0 | FF7: =IF($A7="","",FB7+FD7+FC7) -> 0 | FH7: =IF(FF7="","",FF7-FG7) -> 0 | FI7: =IF(OR($A7="",EZ7=""),"",IF(FF7=0,"No Charges",IF(FH7<=0,"Paid",IF(FG7>0,"Partial","Pending")))) | FM7: =IF($A7="","",SUMIFS('Consumable Usage'!$E:$E,'Consumable Usage'!$A:$A,$A7,'Consumable Usage'!$D:$D,16)) -> 0 | FN7: =IF($A7="","",SUMIFS('Nursing Charges'!$I:$I,'Nursing Charges'!$A:$A,$A7,'Nursing Charges'!$C:$C,16)) -> 0 | FO7: =IF($A7="","",FL7+(FN7-SUMIFS('Nursing Charges'!$J:$J,'Nursing Charges'!$A:$A,$A7,'Nursing Charges'!$C:$C,16))+(FM7-SUMIFS('Consumable Usage'!$F:$F,'Consumable Usage'!$A:$A,$A7,'Consumable Usage'!$D:$D,16))) -> 0 | FP7: =IF($A7="","",FL7+FN7+FM7) -> 0 | FR7: =IF(FP7="","",FP7-FQ7) -> 0 | FS7: =IF(OR($A7="",FJ7=""),"",IF(FP7=0,"No Charges",IF(FR7<=0,"Paid",IF(FQ7>0,"Partial","Pending"))))
A8: CC2026003 | B8: Zara Morani | C8: - | D8: 98213 19074 : Karim Morani | G8: 2026-06-17 | H8: 0 | I8: =IF($A8="","",SUMIFS('Consumable Usage'!$E:$E,'Consumable Usage'!$A:$A,$A8,'Consumable Usage'!$D:$D,1)) -> 1470 | J8: =IF($A8="","",SUMIFS('Nursing Charges'!$I:$I,'Nursing Charges'!$A:$A,$A8,'Nursing Charges'!$C:$C,1)) -> 3500 | K8: =IF($A8="","",H8+(J8-SUMIFS('Nursing Charges'!$J:$J,'Nursing Charges'!$A:$A,$A8,'Nursing Charges'!$C:$C,1))+(I8-SUMIFS('Consumable Usage'!$F:$F,'Consumable Usage'!$A:$A,$A8,'Consumable Usage'!$D:$D,1))) -> 4050 | L8: =IF($A8="","",H8+J8+I8) -> 4970 | N8: =IF(L8="","",L8-M8) -> 4970 | O8: =IF(OR($A8="",F8=""),"",IF(L8=0,"No Charges",IF(N8<=0,"Paid",IF(M8>0,"Partial","Pending")))) | P8: Chemo Infusion + Nursing 24hrs | Q8: 2026-07-28 | R8: 0 | S8: =IF($A8="","",SUMIFS('Consumable Usage'!$E:$E,'Consumable Usage'!$A:$A,$A8,'Consumable Usage'!$D:$D,2)) -> 0 | T8: =IF($A8="","",SUMIFS('Nursing Charges'!$I:$I,'Nursing Charges'!$A:$A,$A8,'Nursing Charges'!$C:$C,2)) -> 3500 | U8: =IF($A8="","",R8+(T8-SUMIFS('Nursing Charges'!$J:$J,'Nursing Charges'!$A:$A,$A8,'Nursing Charges'!$C:$C,2))+(S8-SUMIFS('Consumable Usage'!$F:$F,'Consumable Usage'!$A:$A,$A8,'Consumable Usage'!$D:$D,2))) -> 3500 | V8: =IF($A8="","",R8+T8+S8) -> 3500 | X8: =IF(V8="","",V8-W8) -> 3500 | Y8: =IF(OR($A8="",P8=""),"",IF(V8=0,"No Charges",IF(X8<=0,"Paid",IF(W8>0,"Partial","Pending")))) -> Pending | AC8: =IF($A8="","",SUMIFS('Consumable Usage'!$E:$E,'Consumable Usage'!$A:$A,$A8,'Consumable Usage'!$D:$D,3)) -> 0 | AD8: =IF($A8="","",SUMIFS('Nursing Charges'!$I:$I,'Nursing Charges'!$A:$A,$A8,'Nursing Charges'!$C:$C,3)) -> 0 | AE8: =IF($A8="","",AB8+(AD8-SUMIFS('Nursing Charges'!$J:$J,'Nursing Charges'!$A:$A,$A8,'Nursing Charges'!$C:$C,3))+(AC8-SUMIFS('Consumable Usage'!$F:$F,'Consumable Usage'!$A:$A,$A8,'Consumable Usage'!$D:$D,3))) -> 0 | AF8: =IF($A8="","",AB8+AD8+AC8) -> 0 | AH8: =IF(AF8="","",AF8-AG8) -> 0 | AI8: =IF(OR($A8="",Z8=""),"",IF(AF8=0,"No Charges",IF(AH8<=0,"Paid",IF(AG8>0,"Partial","Pending")))) | AM8: =IF($A8="","",SUMIFS('Consumable Usage'!$E:$E,'Consumable Usage'!$A:$A,$A8,'Consumable Usage'!$D:$D,4)) -> 0 | AN8: =IF($A8="","",SUMIFS('Nursing Charges'!$I:$I,'Nursing Charges'!$A:$A,$A8,'Nursing Charges'!$C:$C,4)) -> 0 | AO8: =IF($A8="","",AL8+(AN8-SUMIFS('Nursing Charges'!$J:$J,'Nursing Charges'!$A:$A,$A8,'Nursing Charges'!$C:$C,4))+(AM8-SUMIFS('Consumable Usage'!$F:$F,'Consumable Usage'!$A:$A,$A8,'Consumable Usage'!$D:$D,4))) -> 0 | AP8: =IF($A8="","",AL8+AN8+AM8) -> 0 | AR8: =IF(AP8="","",AP8-AQ8) -> 0 | AS8: =IF(OR($A8="",AJ8=""),"",IF(AP8=0,"No Charges",IF(AR8<=0,"Paid",IF(AQ8>0,"Partial","Pending")))) | AW8: =IF($A8="","",SUMIFS('Consumable Usage'!$E:$E,'Consumable Usage'!$A:$A,$A8,'Consumable Usage'!$D:$D,5)) -> 0 | AX8: =IF($A8="","",SUMIFS('Nursing Charges'!$I:$I,'Nursing Charges'!$A:$A,$A8,'Nursing Charges'!$C:$C,5)) -> 0 | AY8: =IF($A8="","",AV8+(AX8-SUMIFS('Nursing Charges'!$J:$J,'Nursing Charges'!$A:$A,$A8,'Nursing Charges'!$C:$C,5))+(AW8-SUMIFS('Consumable Usage'!$F:$F,'Consumable Usage'!$A:$A,$A8,'Consumable Usage'!$D:$D,5))) -> 0 | AZ8: =IF($A8="","",AV8+AX8+AW8) -> 0 | BB8: =IF(AZ8="","",AZ8-BA8) -> 0 | BC8: =IF(OR($A8="",AT8=""),"",IF(AZ8=0,"No Charges",IF(BB8<=0,"Paid",IF(BA8>0,"Partial","Pending")))) | BG8: =IF($A8="","",SUMIFS('Consumable Usage'!$E:$E,'Consumable Usage'!$A:$A,$A8,'Consumable Usage'!$D:$D,6)) -> 0 | BH8: =IF($A8="","",SUMIFS('Nursing Charges'!$I:$I,'Nursing Charges'!$A:$A,$A8,'Nursing Charges'!$C:$C,6)) -> 0 | BI8: =IF($A8="","",BF8+(BH8-SUMIFS('Nursing Charges'!$J:$J,'Nursing Charges'!$A:$A,$A8,'Nursing Charges'!$C:$C,6))+(BG8-SUMIFS('Consumable Usage'!$F:$F,'Consumable Usage'!$A:$A,$A8,'Consumable Usage'!$D:$D,6))) -> 0 | BJ8: =IF($A8="","",BF8+BH8+BG8) -> 0 | BL8: =IF(BJ8="","",BJ8-BK8) -> 0 | BM8: =IF(OR($A8="",BD8=""),"",IF(BJ8=0,"No Charges",IF(BL8<=0,"Paid",IF(BK8>0,"Partial","Pending")))) | BQ8: =IF($A8="","",SUMIFS('Consumable Usage'!$E:$E,'Consumable Usage'!$A:$A,$A8,'Consumable Usage'!$D:$D,7)) -> 0 | BR8: =IF($A8="","",SUMIFS('Nursing Charges'!$I:$I,'Nursing Charges'!$A:$A,$A8,'Nursing Charges'!$C:$C,7)) -> 0 | BS8: =IF($A8="","",BP8+(BR8-SUMIFS('Nursing Charges'!$J:$J,'Nursing Charges'!$A:$A,$A8,'Nursing Charges'!$C:$C,7))+(BQ8-SUMIFS('Consumable Usage'!$F:$F,'Consumable Usage'!$A:$A,$A8,'Consumable Usage'!$D:$D,7))) -> 0 | BT8: =IF($A8="","",BP8+BR8+BQ8) -> 0 | BV8: =IF(BT8="","",BT8-BU8) -> 0 | BW8: =IF(OR($A8="",BN8=""),"",IF(BT8=0,"No Charges",IF(BV8<=0,"Paid",IF(BU8>0,"Partial","Pending")))) | CA8: =IF($A8="","",SUMIFS('Consumable Usage'!$E:$E,'Consumable Usage'!$A:$A,$A8,'Consumable Usage'!$D:$D,8)) -> 0 | CB8: =IF($A8="","",SUMIFS('Nursing Charges'!$I:$I,'Nursing Charges'!$A:$A,$A8,'Nursing Charges'!$C:$C,8)) -> 0 | CC8: =IF($A8="","",BZ8+(CB8-SUMIFS('Nursing Charges'!$J:$J,'Nursing Charges'!$A:$A,$A8,'Nursing Charges'!$C:$C,8))+(CA8-SUMIFS('Consumable Usage'!$F:$F,'Consumable Usage'!$A:$A,$A8,'Consumable Usage'!$D:$D,8))) -> 0 | CD8: =IF($A8="","",BZ8+CB8+CA8) -> 0 | CF8: =IF(CD8="","",CD8-CE8) -> 0 | CG8: =IF(OR($A8="",BX8=""),"",IF(CD8=0,"No Charges",IF(CF8<=0,"Paid",IF(CE8>0,"Partial","Pending")))) | CK8: =IF($A8="","",SUMIFS('Consumable Usage'!$E:$E,'Consumable Usage'!$A:$A,$A8,'Consumable Usage'!$D:$D,9)) -> 0 | CL8: =IF($A8="","",SUMIFS('Nursing Charges'!$I:$I,'Nursing Charges'!$A:$A,$A8,'Nursing Charges'!$C:$C,9)) -> 0 | CM8: =IF($A8="","",CJ8+(CL8-SUMIFS('Nursing Charges'!$J:$J,'Nursing Charges'!$A:$A,$A8,'Nursing Charges'!$C:$C,9))+(CK8-SUMIFS('Consumable Usage'!$F:$F,'Consumable Usage'!$A:$A,$A8,'Consumable Usage'!$D:$D,9))) -> 0 | CN8: =IF($A8="","",CJ8+CL8+CK8) -> 0 | CP8: =IF(CN8="","",CN8-CO8) -> 0 | CQ8: =IF(OR($A8="",CH8=""),"",IF(CN8=0,"No Charges",IF(CP8<=0,"Paid",IF(CO8>0,"Partial","Pending")))) | CU8: =IF($A8="","",SUMIFS('Consumable Usage'!$E:$E,'Consumable Usage'!$A:$A,$A8,'Consumable Usage'!$D:$D,10)) -> 0 | CV8: =IF($A8="","",SUMIFS('Nursing Charges'!$I:$I,'Nursing Charges'!$A:$A,$A8,'Nursing Charges'!$C:$C,10)) -> 0 | CW8: =IF($A8="","",CT8+(CV8-SUMIFS('Nursing Charges'!$J:$J,'Nursing Charges'!$A:$A,$A8,'Nursing Charges'!$C:$C,10))+(CU8-SUMIFS('Consumable Usage'!$F:$F,'Consumable Usage'!$A:$A,$A8,'Consumable Usage'!$D:$D,10))) -> 0 | CX8: =IF($A8="","",CT8+CV8+CU8) -> 0 | CZ8: =IF(CX8="","",CX8-CY8) -> 0 | DA8: =IF(OR($A8="",CR8=""),"",IF(CX8=0,"No Charges",IF(CZ8<=0,"Paid",IF(CY8>0,"Partial","Pending")))) | DE8: =IF($A8="","",SUMIFS('Consumable Usage'!$E:$E,'Consumable Usage'!$A:$A,$A8,'Consumable Usage'!$D:$D,11)) -> 0 | DF8: =IF($A8="","",SUMIFS('Nursing Charges'!$I:$I,'Nursing Charges'!$A:$A,$A8,'Nursing Charges'!$C:$C,11)) -> 0 | DG8: =IF($A8="","",DD8+(DF8-SUMIFS('Nursing Charges'!$J:$J,'Nursing Charges'!$A:$A,$A8,'Nursing Charges'!$C:$C,11))+(DE8-SUMIFS('Consumable Usage'!$F:$F,'Consumable Usage'!$A:$A,$A8,'Consumable Usage'!$D:$D,11))) -> 0 | DH8: =IF($A8="","",DD8+DF8+DE8) -> 0 | DJ8: =IF(DH8="","",DH8-DI8) -> 0 | DK8: =IF(OR($A8="",DB8=""),"",IF(DH8=0,"No Charges",IF(DJ8<=0,"Paid",IF(DI8>0,"Partial","Pending")))) | DO8: =IF($A8="","",SUMIFS('Consumable Usage'!$E:$E,'Consumable Usage'!$A:$A,$A8,'Consumable Usage'!$D:$D,12)) -> 0 | DP8: =IF($A8="","",SUMIFS('Nursing Charges'!$I:$I,'Nursing Charges'!$A:$A,$A8,'Nursing Charges'!$C:$C,12)) -> 0 | DQ8: =IF($A8="","",DN8+(DP8-SUMIFS('Nursing Charges'!$J:$J,'Nursing Charges'!$A:$A,$A8,'Nursing Charges'!$C:$C,12))+(DO8-SUMIFS('Consumable Usage'!$F:$F,'Consumable Usage'!$A:$A,$A8,'Consumable Usage'!$D:$D,12))) -> 0 | DR8: =IF($A8="","",DN8+DP8+DO8) -> 0 | DT8: =IF(DR8="","",DR8-DS8) -> 0 | DU8: =IF(OR($A8="",DL8=""),"",IF(DR8=0,"No Charges",IF(DT8<=0,"Paid",IF(DS8>0,"Partial","Pending")))) | DY8: =IF($A8="","",SUMIFS('Consumable Usage'!$E:$E,'Consumable Usage'!$A:$A,$A8,'Consumable Usage'!$D:$D,13)) -> 0 | DZ8: =IF($A8="","",SUMIFS('Nursing Charges'!$I:$I,'Nursing Charges'!$A:$A,$A8,'Nursing Charges'!$C:$C,13)) -> 0 | EA8: =IF($A8="","",DX8+(DZ8-SUMIFS('Nursing Charges'!$J:$J,'Nursing Charges'!$A:$A,$A8,'Nursing Charges'!$C:$C,13))+(DY8-SUMIFS('Consumable Usage'!$F:$F,'Consumable Usage'!$A:$A,$A8,'Consumable Usage'!$D:$D,13))) -> 0 | EB8: =IF($A8="","",DX8+DZ8+DY8) -> 0 | ED8: =IF(EB8="","",EB8-EC8) -> 0 | EE8: =IF(OR($A8="",DV8=""),"",IF(EB8=0,"No Charges",IF(ED8<=0,"Paid",IF(EC8>0,"Partial","Pending")))) | EI8: =IF($A8="","",SUMIFS('Consumable Usage'!$E:$E,'Consumable Usage'!$A:$A,$A8,'Consumable Usage'!$D:$D,14)) -> 0 | EJ8: =IF($A8="","",SUMIFS('Nursing Charges'!$I:$I,'Nursing Charges'!$A:$A,$A8,'Nursing Charges'!$C:$C,14)) -> 0 | EK8: =IF($A8="","",EH8+(EJ8-SUMIFS('Nursing Charges'!$J:$J,'Nursing Charges'!$A:$A,$A8,'Nursing Charges'!$C:$C,14))+(EI8-SUMIFS('Consumable Usage'!$F:$F,'Consumable Usage'!$A:$A,$A8,'Consumable Usage'!$D:$D,14))) -> 0 | EL8: =IF($A8="","",EH8+EJ8+EI8) -> 0 | EN8: =IF(EL8="","",EL8-EM8) -> 0 | EO8: =IF(OR($A8="",EF8=""),"",IF(EL8=0,"No Charges",IF(EN8<=0,"Paid",IF(EM8>0,"Partial","Pending")))) | ES8: =IF($A8="","",SUMIFS('Consumable Usage'!$E:$E,'Consumable Usage'!$A:$A,$A8,'Consumable Usage'!$D:$D,15)) -> 0 | ET8: =IF($A8="","",SUMIFS('Nursing Charges'!$I:$I,'Nursing Charges'!$A:$A,$A8,'Nursing Charges'!$C:$C,15)) -> 0 | EU8: =IF($A8="","",ER8+(ET8-SUMIFS('Nursing Charges'!$J:$J,'Nursing Charges'!$A:$A,$A8,'Nursing Charges'!$C:$C,15))+(ES8-SUMIFS('Consumable Usage'!$F:$F,'Consumable Usage'!$A:$A,$A8,'Consumable Usage'!$D:$D,15))) -> 0 | EV8: =IF($A8="","",ER8+ET8+ES8) -> 0 | EX8: =IF(EV8="","",EV8-EW8) -> 0 | EY8: =IF(OR($A8="",EP8=""),"",IF(EV8=0,"No Charges",IF(EX8<=0,"Paid",IF(EW8>0,"Partial","Pending")))) | FC8: =IF($A8="","",SUMIFS('Consumable Usage'!$E:$E,'Consumable Usage'!$A:$A,$A8,'Consumable Usage'!$D:$D,16)) -> 0 | FD8: =IF($A8="","",SUMIFS('Nursing Charges'!$I:$I,'Nursing Charges'!$A:$A,$A8,'Nursing Charges'!$C:$C,16)) -> 0 | FE8: =IF($A8="","",FB8+(FD8-SUMIFS('Nursing Charges'!$J:$J,'Nursing Charges'!$A:$A,$A8,'Nursing Charges'!$C:$C,16))+(FC8-SUMIFS('Consumable Usage'!$F:$F,'Consumable Usage'!$A:$A,$A8,'Consumable Usage'!$D:$D,16))) -> 0 | FF8: =IF($A8="","",FB8+FD8+FC8) -> 0 | FH8: =IF(FF8="","",FF8-FG8) -> 0 | FI8: =IF(OR($A8="",EZ8=""),"",IF(FF8=0,"No Charges",IF(FH8<=0,"Paid",IF(FG8>0,"Partial","Pending")))) | FM8: =IF($A8="","",SUMIFS('Consumable Usage'!$E:$E,'Consumable Usage'!$A:$A,$A8,'Consumable Usage'!$D:$D,16)) -> 0 | FN8: =IF($A8="","",SUMIFS('Nursing Charges'!$I:$I,'Nursing Charges'!$A:$A,$A8,'Nursing Charges'!$C:$C,16)) -> 0 | FO8: =IF($A8="","",FL8+(FN8-SUMIFS('Nursing Charges'!$J:$J,'Nursing Charges'!$A:$A,$A8,'Nursing Charges'!$C:$C,16))+(FM8-SUMIFS('Consumable Usage'!$F:$F,'Consumable Usage'!$A:$A,$A8,'Consumable Usage'!$D:$D,16))) -> 0 | FP8: =IF($A8="","",FL8+FN8+FM8) -> 0 | FR8: =IF(FP8="","",FP8-FQ8) -> 0 | FS8: =IF(OR($A8="",FJ8=""),"",IF(FP8=0,"No Charges",IF(FR8<=0,"Paid",IF(FQ8>0,"Partial","Pending"))))
A9: CC2026004 | B9: Sanjay Shorewala | C9: KOMAL | D9: 98208 60967 | E9: get the next dates | G9: 2026-07-23 | H9: 0 | I9: =IF($A9="","",SUMIFS('Consumable Usage'!$E:$E,'Consumable Usage'!$A:$A,$A9,'Consumable Usage'!$D:$D,1)) -> 0 | J9: =IF($A9="","",SUMIFS('Nursing Charges'!$I:$I,'Nursing Charges'!$A:$A,$A9,'Nursing Charges'!$C:$C,1)) -> 0 | K9: =IF($A9="","",H9+(J9-SUMIFS('Nursing Charges'!$J:$J,'Nursing Charges'!$A:$A,$A9,'Nursing Charges'!$C:$C,1))+(I9-SUMIFS('Consumable Usage'!$F:$F,'Consumable Usage'!$A:$A,$A9,'Consumable Usage'!$D:$D,1))) -> 0 | L9: =IF($A9="","",H9+J9+I9) -> 0 | N9: =IF(L9="","",L9-M9) -> 0 | O9: =IF(OR($A9="",F9=""),"",IF(L9=0,"No Charges",IF(N9<=0,"Paid",IF(M9>0,"Partial","Pending")))) | P9: Nursing 24hrs | Q9: 2026-07-31 | R9: 0 | S9: =IF($A9="","",SUMIFS('Consumable Usage'!$E:$E,'Consumable Usage'!$A:$A,$A9,'Consumable Usage'!$D:$D,2)) -> 0 | T9: =IF($A9="","",SUMIFS('Nursing Charges'!$I:$I,'Nursing Charges'!$A:$A,$A9,'Nursing Charges'!$C:$C,2)) -> 0 | U9: =IF($A9="","",R9+(T9-SUMIFS('Nursing Charges'!$J:$J,'Nursing Charges'!$A:$A,$A9,'Nursing Charges'!$C:$C,2))+(S9-SUMIFS('Consumable Usage'!$F:$F,'Consumable Usage'!$A:$A,$A9,'Consumable Usage'!$D:$D,2))) -> 0 | V9: =IF($A9="","",R9+T9+S9) -> 0 | X9: =IF(V9="","",V9-W9) -> 0 | Y9: =IF(OR($A9="",P9=""),"",IF(V9=0,"No Charges",IF(X9<=0,"Paid",IF(W9>0,"Partial","Pending")))) -> No Charges | Z9: Nursing 24hrs | AA9: 2026-08-01 | AB9: 0 | AC9: =IF($A9="","",SUMIFS('Consumable Usage'!$E:$E,'Consumable Usage'!$A:$A,$A9,'Consumable Usage'!$D:$D,3)) -> 0 | AD9: =IF($A9="","",SUMIFS('Nursing Charges'!$I:$I,'Nursing Charges'!$A:$A,$A9,'Nursing Charges'!$C:$C,3)) -> 0 | AE9: =IF($A9="","",AB9+(AD9-SUMIFS('Nursing Charges'!$J:$J,'Nursing Charges'!$A:$A,$A9,'Nursing Charges'!$C:$C,3))+(AC9-SUMIFS('Consumable Usage'!$F:$F,'Consumable Usage'!$A:$A,$A9,'Consumable Usage'!$D:$D,3))) -> 0 | AF9: =IF($A9="","",AB9+AD9+AC9) -> 0 | AH9: =IF(AF9="","",AF9-AG9) -> 0 | AI9: =IF(OR($A9="",Z9=""),"",IF(AF9=0,"No Charges",IF(AH9<=0,"Paid",IF(AG9>0,"Partial","Pending")))) -> No Charges | AM9: =IF($A9="","",SUMIFS('Consumable Usage'!$E:$E,'Consumable Usage'!$A:$A,$A9,'Consumable Usage'!$D:$D,4)) -> 0 | AN9: =IF($A9="","",SUMIFS('Nursing Charges'!$I:$I,'Nursing Charges'!$A:$A,$A9,'Nursing Charges'!$C:$C,4)) -> 0 | AO9: =IF($A9="","",AL9+(AN9-SUMIFS('Nursing Charges'!$J:$J,'Nursing Charges'!$A:$A,$A9,'Nursing Charges'!$C:$C,4))+(AM9-SUMIFS('Consumable Usage'!$F:$F,'Consumable Usage'!$A:$A,$A9,'Consumable Usage'!$D:$D,4))) -> 0 | AP9: =IF($A9="","",AL9+AN9+AM9) -> 0 | AR9: =IF(AP9="","",AP9-AQ9) -> 0 | AS9: =IF(OR($A9="",AJ9=""),"",IF(AP9=0,"No Charges",IF(AR9<=0,"Paid",IF(AQ9>0,"Partial","Pending")))) | AW9: =IF($A9="","",SUMIFS('Consumable Usage'!$E:$E,'Consumable Usage'!$A:$A,$A9,'Consumable Usage'!$D:$D,5)) -> 0 | AX9: =IF($A9="","",SUMIFS('Nursing Charges'!$I:$I,'Nursing Charges'!$A:$A,$A9,'Nursing Charges'!$C:$C,5)) -> 0 | AY9: =IF($A9="","",AV9+(AX9-SUMIFS('Nursing Charges'!$J:$J,'Nursing Charges'!$A:$A,$A9,'Nursing Charges'!$C:$C,5))+(AW9-SUMIFS('Consumable Usage'!$F:$F,'Consumable Usage'!$A:$A,$A9,'Consumable Usage'!$D:$D,5))) -> 0 | AZ9: =IF($A9="","",AV9+AX9+AW9) -> 0 | BB9: =IF(AZ9="","",AZ9-BA9) -> 0 | BC9: =IF(OR($A9="",AT9=""),"",IF(AZ9=0,"No Charges",IF(BB9<=0,"Paid",IF(BA9>0,"Partial","Pending")))) | BG9: =IF($A9="","",SUMIFS('Consumable Usage'!$E:$E,'Consumable Usage'!$A:$A,$A9,'Consumable Usage'!$D:$D,6)) -> 0 | BH9: =IF($A9="","",SUMIFS('Nursing Charges'!$I:$I,'Nursing Charges'!$A:$A,$A9,'Nursing Charges'!$C:$C,6)) -> 0 | BI9: =IF($A9="","",BF9+(BH9-SUMIFS('Nursing Charges'!$J:$J,'Nursing Charges'!$A:$A,$A9,'Nursing Charges'!$C:$C,6))+(BG9-SUMIFS('Consumable Usage'!$F:$F,'Consumable Usage'!$A:$A,$A9,'Consumable Usage'!$D:$D,6))) -> 0 | BJ9: =IF($A9="","",BF9+BH9+BG9) -> 0 | BL9: =IF(BJ9="","",BJ9-BK9) -> 0 | BM9: =IF(OR($A9="",BD9=""),"",IF(BJ9=0,"No Charges",IF(BL9<=0,"Paid",IF(BK9>0,"Partial","Pending")))) | BQ9: =IF($A9="","",SUMIFS('Consumable Usage'!$E:$E,'Consumable Usage'!$A:$A,$A9,'Consumable Usage'!$D:$D,7)) -> 0 | BR9: =IF($A9="","",SUMIFS('Nursing Charges'!$I:$I,'Nursing Charges'!$A:$A,$A9,'Nursing Charges'!$C:$C,7)) -> 0 | BS9: =IF($A9="","",BP9+(BR9-SUMIFS('Nursing Charges'!$J:$J,'Nursing Charges'!$A:$A,$A9,'Nursing Charges'!$C:$C,7))+(BQ9-SUMIFS('Consumable Usage'!$F:$F,'Consumable Usage'!$A:$A,$A9,'Consumable Usage'!$D:$D,7))) -> 0 | BT9: =IF($A9="","",BP9+BR9+BQ9) -> 0 | BV9: =IF(BT9="","",BT9-BU9) -> 0 | BW9: =IF(OR($A9="",BN9=""),"",IF(BT9=0,"No Charges",IF(BV9<=0,"Paid",IF(BU9>0,"Partial","Pending")))) | CA9: =IF($A9="","",SUMIFS('Consumable Usage'!$E:$E,'Consumable Usage'!$A:$A,$A9,'Consumable Usage'!$D:$D,8)) -> 0 | CB9: =IF($A9="","",SUMIFS('Nursing Charges'!$I:$I,'Nursing Charges'!$A:$A,$A9,'Nursing Charges'!$C:$C,8)) -> 0 | CC9: =IF($A9="","",BZ9+(CB9-SUMIFS('Nursing Charges'!$J:$J,'Nursing Charges'!$A:$A,$A9,'Nursing Charges'!$C:$C,8))+(CA9-SUMIFS('Consumable Usage'!$F:$F,'Consumable Usage'!$A:$A,$A9,'Consumable Usage'!$D:$D,8))) -> 0 | CD9: =IF($A9="","",BZ9+CB9+CA9) -> 0 | CF9: =IF(CD9="","",CD9-CE9) -> 0 | CG9: =IF(OR($A9="",BX9=""),"",IF(CD9=0,"No Charges",IF(CF9<=0,"Paid",IF(CE9>0,"Partial","Pending")))) | CK9: =IF($A9="","",SUMIFS('Consumable Usage'!$E:$E,'Consumable Usage'!$A:$A,$A9,'Consumable Usage'!$D:$D,9)) -> 0 | CL9: =IF($A9="","",SUMIFS('Nursing Charges'!$I:$I,'Nursing Charges'!$A:$A,$A9,'Nursing Charges'!$C:$C,9)) -> 0 | CM9: =IF($A9="","",CJ9+(CL9-SUMIFS('Nursing Charges'!$J:$J,'Nursing Charges'!$A:$A,$A9,'Nursing Charges'!$C:$C,9))+(CK9-SUMIFS('Consumable Usage'!$F:$F,'Consumable Usage'!$A:$A,$A9,'Consumable Usage'!$D:$D,9))) -> 0 | CN9: =IF($A9="","",CJ9+CL9+CK9) -> 0 | CP9: =IF(CN9="","",CN9-CO9) -> 0 | CQ9: =IF(OR($A9="",CH9=""),"",IF(CN9=0,"No Charges",IF(CP9<=0,"Paid",IF(CO9>0,"Partial","Pending")))) | CU9: =IF($A9="","",SUMIFS('Consumable Usage'!$E:$E,'Consumable Usage'!$A:$A,$A9,'Consumable Usage'!$D:$D,10)) -> 0 | CV9: =IF($A9="","",SUMIFS('Nursing Charges'!$I:$I,'Nursing Charges'!$A:$A,$A9,'Nursing Charges'!$C:$C,10)) -> 0 | CW9: =IF($A9="","",CT9+(CV9-SUMIFS('Nursing Charges'!$J:$J,'Nursing Charges'!$A:$A,$A9,'Nursing Charges'!$C:$C,10))+(CU9-SUMIFS('Consumable Usage'!$F:$F,'Consumable Usage'!$A:$A,$A9,'Consumable Usage'!$D:$D,10))) -> 0 | CX9: =IF($A9="","",CT9+CV9+CU9) -> 0 | CZ9: =IF(CX9="","",CX9-CY9) -> 0 | DA9: =IF(OR($A9="",CR9=""),"",IF(CX9=0,"No Charges",IF(CZ9<=0,"Paid",IF(CY9>0,"Partial","Pending")))) | DE9: =IF($A9="","",SUMIFS('Consumable Usage'!$E:$E,'Consumable Usage'!$A:$A,$A9,'Consumable Usage'!$D:$D,11)) -> 0 | DF9: =IF($A9="","",SUMIFS('Nursing Charges'!$I:$I,'Nursing Charges'!$A:$A,$A9,'Nursing Charges'!$C:$C,11)) -> 0 | DG9: =IF($A9="","",DD9+(DF9-SUMIFS('Nursing Charges'!$J:$J,'Nursing Charges'!$A:$A,$A9,'Nursing Charges'!$C:$C,11))+(DE9-SUMIFS('Consumable Usage'!$F:$F,'Consumable Usage'!$A:$A,$A9,'Consumable Usage'!$D:$D,11))) -> 0 | DH9: =IF($A9="","",DD9+DF9+DE9) -> 0 | DJ9: =IF(DH9="","",DH9-DI9) -> 0 | DK9: =IF(OR($A9="",DB9=""),"",IF(DH9=0,"No Charges",IF(DJ9<=0,"Paid",IF(DI9>0,"Partial","Pending")))) | DO9: =IF($A9="","",SUMIFS('Consumable Usage'!$E:$E,'Consumable Usage'!$A:$A,$A9,'Consumable Usage'!$D:$D,12)) -> 0 | DP9: =IF($A9="","",SUMIFS('Nursing Charges'!$I:$I,'Nursing Charges'!$A:$A,$A9,'Nursing Charges'!$C:$C,12)) -> 0 | DQ9: =IF($A9="","",DN9+(DP9-SUMIFS('Nursing Charges'!$J:$J,'Nursing Charges'!$A:$A,$A9,'Nursing Charges'!$C:$C,12))+(DO9-SUMIFS('Consumable Usage'!$F:$F,'Consumable Usage'!$A:$A,$A9,'Consumable Usage'!$D:$D,12))) -> 0 | DR9: =IF($A9="","",DN9+DP9+DO9) -> 0 | DT9: =IF(DR9="","",DR9-DS9) -> 0 | DU9: =IF(OR($A9="",DL9=""),"",IF(DR9=0,"No Charges",IF(DT9<=0,"Paid",IF(DS9>0,"Partial","Pending")))) | DY9: =IF($A9="","",SUMIFS('Consumable Usage'!$E:$E,'Consumable Usage'!$A:$A,$A9,'Consumable Usage'!$D:$D,13)) -> 0 | DZ9: =IF($A9="","",SUMIFS('Nursing Charges'!$I:$I,'Nursing Charges'!$A:$A,$A9,'Nursing Charges'!$C:$C,13)) -> 0 | EA9: =IF($A9="","",DX9+(DZ9-SUMIFS('Nursing Charges'!$J:$J,'Nursing Charges'!$A:$A,$A9,'Nursing Charges'!$C:$C,13))+(DY9-SUMIFS('Consumable Usage'!$F:$F,'Consumable Usage'!$A:$A,$A9,'Consumable Usage'!$D:$D,13))) -> 0 | EB9: =IF($A9="","",DX9+DZ9+DY9) -> 0 | ED9: =IF(EB9="","",EB9-EC9) -> 0 | EE9: =IF(OR($A9="",DV9=""),"",IF(EB9=0,"No Charges",IF(ED9<=0,"Paid",IF(EC9>0,"Partial","Pending")))) | EI9: =IF($A9="","",SUMIFS('Consumable Usage'!$E:$E,'Consumable Usage'!$A:$A,$A9,'Consumable Usage'!$D:$D,14)) -> 0 | EJ9: =IF($A9="","",SUMIFS('Nursing Charges'!$I:$I,'Nursing Charges'!$A:$A,$A9,'Nursing Charges'!$C:$C,14)) -> 0 | EK9: =IF($A9="","",EH9+(EJ9-SUMIFS('Nursing Charges'!$J:$J,'Nursing Charges'!$A:$A,$A9,'Nursing Charges'!$C:$C,14))+(EI9-SUMIFS('Consumable Usage'!$F:$F,'Consumable Usage'!$A:$A,$A9,'Consumable Usage'!$D:$D,14))) -> 0 | EL9: =IF($A9="","",EH9+EJ9+EI9) -> 0 | EN9: =IF(EL9="","",EL9-EM9) -> 0 | EO9: =IF(OR($A9="",EF9=""),"",IF(EL9=0,"No Charges",IF(EN9<=0,"Paid",IF(EM9>0,"Partial","Pending")))) | ES9: =IF($A9="","",SUMIFS('Consumable Usage'!$E:$E,'Consumable Usage'!$A:$A,$A9,'Consumable Usage'!$D:$D,15)) -> 0 | ET9: =IF($A9="","",SUMIFS('Nursing Charges'!$I:$I,'Nursing Charges'!$A:$A,$A9,'Nursing Charges'!$C:$C,15)) -> 0 | EU9: =IF($A9="","",ER9+(ET9-SUMIFS('Nursing Charges'!$J:$J,'Nursing Charges'!$A:$A,$A9,'Nursing Charges'!$C:$C,15))+(ES9-SUMIFS('Consumable Usage'!$F:$F,'Consumable Usage'!$A:$A,$A9,'Consumable Usage'!$D:$D,15))) -> 0 | EV9: =IF($A9="","",ER9+ET9+ES9) -> 0 | EX9: =IF(EV9="","",EV9-EW9) -> 0 | EY9: =IF(OR($A9="",EP9=""),"",IF(EV9=0,"No Charges",IF(EX9<=0,"Paid",IF(EW9>0,"Partial","Pending")))) | FC9: =IF($A9="","",SUMIFS('Consumable Usage'!$E:$E,'Consumable Usage'!$A:$A,$A9,'Consumable Usage'!$D:$D,16)) -> 0 | FD9: =IF($A9="","",SUMIFS('Nursing Charges'!$I:$I,'Nursing Charges'!$A:$A,$A9,'Nursing Charges'!$C:$C,16)) -> 0 | FE9: =IF($A9="","",FB9+(FD9-SUMIFS('Nursing Charges'!$J:$J,'Nursing Charges'!$A:$A,$A9,'Nursing Charges'!$C:$C,16))+(FC9-SUMIFS('Consumable Usage'!$F:$F,'Consumable Usage'!$A:$A,$A9,'Consumable Usage'!$D:$D,16))) -> 0 | FF9: =IF($A9="","",FB9+FD9+FC9) -> 0 | FH9: =IF(FF9="","",FF9-FG9) -> 0 | FI9: =IF(OR($A9="",EZ9=""),"",IF(FF9=0,"No Charges",IF(FH9<=0,"Paid",IF(FG9>0,"Partial","Pending")))) | FM9: =IF($A9="","",SUMIFS('Consumable Usage'!$E:$E,'Consumable Usage'!$A:$A,$A9,'Consumable Usage'!$D:$D,16)) -> 0 | FN9: =IF($A9="","",SUMIFS('Nursing Charges'!$I:$I,'Nursing Charges'!$A:$A,$A9,'Nursing Charges'!$C:$C,16)) -> 0 | FO9: =IF($A9="","",FL9+(FN9-SUMIFS('Nursing Charges'!$J:$J,'Nursing Charges'!$A:$A,$A9,'Nursing Charges'!$C:$C,16))+(FM9-SUMIFS('Consumable Usage'!$F:$F,'Consumable Usage'!$A:$A,$A9,'Consumable Usage'!$D:$D,16))) -> 0 | FP9: =IF($A9="","",FL9+FN9+FM9) -> 0 | FR9: =IF(FP9="","",FP9-FQ9) -> 0 | FS9: =IF(OR($A9="",FJ9=""),"",IF(FP9=0,"No Charges",IF(FR9<=0,"Paid",IF(FQ9>0,"Partial","Pending"))))
